Workbook

Sheet Management
B3: Telecom Summery
B4: (Country) | C4: Cost USD | H4: Tokens
B5: (Short \ decdicated \ Sim host) | H5: input tokens costs | I5: =0.25/1000000 -> 2.5e-07
B6: outbund | C6: =G45 -> 0.0853425 | H6: output tokens costs | I6: =1.5/1000000 -> 1.5e-06
B7: inbund | C7: =D45 -> 0.011379
B8: setup - monthly \ yearly (in a month) | C8: =D36 -> 22.64421 | D8: =D37 -> 11.26521
B9: subscription - monthly \ yearly (in a month) | C9: =G36+G38 -> 93.02321 | D9: =G37+G38 -> 81.64421
B11: Number of contacts | C11: 165
A15: SMS Cost Per Country
B16: out | M16: in
B17: tier 1 | F17: tier 2 | J17: tier 2
B18: local | C18: usd | E18: message volume | F18: local | H18: usd | I18: message volume | J18: local | K18: usd | L18: scope | M18: local | N18: usd
A19: Kenya | B19: 0.8 | C19: =IFERROR(__xludf.DUMMYFUNCTION("GOOGLEFINANCE(""CURRENCY:KESUSD"") * B19"),0.006181902480000001) -> 0.0061819025 | E19: 0 - 99,999 KES | F19: 0.7 | H19: =IFERROR(__xludf.DUMMYFUNCTION("GOOGLEFINANCE(""CURRENCY:KESUSD"") * F19"),0.00540916467) -> 0.0054091647 | I19: 100,000 - 399,999 KES | J19: 0.6 | K19: =IFERROR(__xludf.DUMMYFUNCTION("GOOGLEFINANCE(""CURRENCY:KESUSD"") * J19"),0.00463642686) -> 0.0046364269 | L19: 400,000+ KES
A21: Ethiopia | B21: 0.012 | C21: =IFERROR(__xludf.DUMMYFUNCTION("GOOGLEFINANCE(""CURRENCY:EURUSD"") * B21"),0.0136548) -> 0.0136548
A22: Tanzania | B22: 22 | C22: =IFERROR(__xludf.DUMMYFUNCTION("GOOGLEFINANCE(""CURRENCY:TZSUSD"") * B22"),0.008380942811999999) -> 0.0083809428 | E22: TZS 0 - 499,999 | F22: 20 | H22: =IFERROR(__xludf.DUMMYFUNCTION("GOOGLEFINANCE(""CURRENCY:TZSUSD"") * F22"),0.00761903892) -> 0.0076190389 | I22: TZS 500,000 - 2,499,999 | M22: 150 | N22: =IFERROR(__xludf.DUMMYFUNCTION("GOOGLEFINANCE(""CURRENCY:TZSUSD"") * M22"),0.057142791899999996) -> 0.057142792
C27: set app | F27: monthly fee | I27: yearly (Paid From Second Year)
A28: Shortcode by country | C28: local | D28: usd | E28: eur | F28: local | G28: usd | H28: eur | I28: local | J28: usd | K28: sum local | L28: sum used
A29: Kenya | B29: dedecated | C29: 6728 | D29: =IFERROR(__xludf.DUMMYFUNCTION("GOOGLEFINANCE(""CURRENCY:KESUSD"") * C29"),51.989799856800005) -> 51.9898 | F29: 80736 | G29: =IFERROR(__xludf.DUMMYFUNCTION("GOOGLEFINANCE(""CURRENCY:KESUSD"") *F29"),623.8775982816001) -> 623.8776
B30: Shared | C30: 5800 | D30: =IFERROR(__xludf.DUMMYFUNCTION("GOOGLEFINANCE(""CURRENCY:KESUSD"") * C30"),44.818792980000005) -> 44.818793 | F30: 2320 | G30: =IFERROR(__xludf.DUMMYFUNCTION("GOOGLEFINANCE(""CURRENCY:KESUSD"") *F30"),17.927517192) -> 17.927517
A31: Zambia | B31: dedecated | C31: 700 | D31: =IFERROR(__xludf.DUMMYFUNCTION("GOOGLEFINANCE(""CURRENCY:ZMWUSD"") * C31"),39.017741) -> 39.017741 | F31: 1500 | G31: =IFERROR(__xludf.DUMMYFUNCTION("GOOGLEFINANCE(""CURRENCY:ZMWUSD"") * F31"),83.609445) -> 83.609445
B32: Shared | C32: 700 | D32: =IFERROR(__xludf.DUMMYFUNCTION("GOOGLEFINANCE(""CURRENCY:ZMWUSD"") * C32"),39.017741) -> 39.017741 | F32: 500 | G32: =IFERROR(__xludf.DUMMYFUNCTION("GOOGLEFINANCE(""CURRENCY:ZMWUSD"") * F32"),27.869815) -> 27.869815
A33: Ethiopia | B33: dedecates short code | C33: 1000EUR | D33: - | F33: -
A34: Tanzania | B34: dedecated | C34: =IFERROR(__xludf.DUMMYFUNCTION("GOOGLEFINANCE(""CURRENCY:USDTZS"") * D34"),1.3412513501769342E7) -> 13412514 | D34: =IFERROR(__xludf.DUMMYFUNCTION("4500 + GOOGLEFINANCE(""CURRENCY:TZSUSD"") * 1600000"),5109.5231136) -> 5109.5231 | I34: 4600000 | J34: 3050 | K34: =IFERROR(__xludf.DUMMYFUNCTION("I34+ GOOGLEFINANCE(""CURRENCY:USDTZS"") * J34"),1.260625915E7) -> 12606259 | L34: =IFERROR(__xludf.DUMMYFUNCTION("J34+ GOOGLEFINANCE(""CURRENCY:TZSUSD"") * I34"),4802.3789516) -> 4802.379
B35: Shared | C35: 198500 | D35: =IFERROR(__xludf.DUMMYFUNCTION("GOOGLEFINANCE(""CURRENCY:TZSUSD"") * C35"),75.618961281) -> 75.618961 | F35: 79400 | G35: =IFERROR(__xludf.DUMMYFUNCTION("GOOGLEFINANCE(""CURRENCY:TZSUSD"") * F35"),30.2475845124) -> 30.247585
A36: Sim hosting - seven | B36: mothly | C36: =IFERROR(__xludf.DUMMYFUNCTION("GOOGLEFINANCE(""CURRENCY:EURTZS"") * E36"),59554.73) -> 59554.73 | D36: =IFERROR(__xludf.DUMMYFUNCTION("GOOGLEFINANCE(""CURRENCY:EURUSD"") * E36"),22.644209999999998) -> 22.64421 | E36: 19.9 | F36: =IFERROR(__xludf.DUMMYFUNCTION("GOOGLEFINANCE(""CURRENCY:EURTZS"") * H36"),89481.73000000001) -> 89481.73 | G36: =IFERROR(__xludf.DUMMYFUNCTION("GOOGLEFINANCE(""CURRENCY:EURUSD"") * H36"),34.02321) -> 34.02321 | H36: 29.9
B37: yearly | C37: =IFERROR(__xludf.DUMMYFUNCTION("GOOGLEFINANCE(""CURRENCY:EURTZS"") * E37"),29627.730000000003) -> 29627.73 | D37: =IFERROR(__xludf.DUMMYFUNCTION("GOOGLEFINANCE(""CURRENCY:EURUSD"") * E37"),11.26521) -> 11.26521 | E37: 9.9 | F37: =IFERROR(__xludf.DUMMYFUNCTION("GOOGLEFINANCE(""CURRENCY:EURTZS"") * H37"),59554.73) -> 59554.73 | G37: =IFERROR(__xludf.DUMMYFUNCTION("GOOGLEFINANCE(""CURRENCY:EURUSD"") * H37"),22.644209999999998) -> 22.64421 | H37: 19.9
A38: Whatsupp | G38: 59
A39: South Africa | B39: dedecated | C39: 4200 | D39: =IFERROR(__xludf.DUMMYFUNCTION("GOOGLEFINANCE(""CURRENCY:ZARUSD"") * C39"),254.42075400000002) -> 254.42075 | E39: 1200 | F39: =IFERROR(__xludf.DUMMYFUNCTION("GOOGLEFINANCE(""CURRENCY:ZARUSD"") *E39"),72.69164400000001) -> 72.691644 | G39: =IFERROR(__xludf.DUMMYFUNCTION("GOOGLEFINANCE(""CURRENCY:ZARUSD"") * F39"),4.4033959228522805) -> 4.4033959
B40: Shared
B42: Sim hosting - seven | C42: inbound - per SMS (160 characters) | F42: outbund
C43: local | D43: usd | E43: eur | F43: local | G43: usd | H43: eur
B44: Tanzania | C44: =IFERROR(__xludf.DUMMYFUNCTION("GOOGLEFINANCE(""CURRENCY:EURTZS"") * E44"),29.927000000000003) -> 29.927 | D44: =IFERROR(__xludf.DUMMYFUNCTION("GOOGLEFINANCE(""CURRENCY:EURUSD"") * E44"),0.011378999999999998) -> 0.011379 | E44: 0.01 | F44: =IFERROR(__xludf.DUMMYFUNCTION("GOOGLEFINANCE(""CURRENCY:EURTZS"") * H44"),879.8538) -> 879.8538 | G44: =IFERROR(__xludf.DUMMYFUNCTION("GOOGLEFINANCE(""CURRENCY:EURUSD"") * H44"),0.33454259999999997) -> 0.3345426 | H44: 0.294
B45: SouthAfrica | C45: =IFERROR(__xludf.DUMMYFUNCTION("GOOGLEFINANCE(""CURRENCY:USDZAR"") * D45"),0.1878456699) -> 0.18784567 | D45: =IFERROR(__xludf.DUMMYFUNCTION("GOOGLEFINANCE(""CURRENCY:EURUSD"") * E44"),0.011378999999999998) -> 0.011379 | E45: 0.01 | F45: =IFERROR(__xludf.DUMMYFUNCTION("GOOGLEFINANCE(""CURRENCY:USDZAR"") * H45"),1.2381075000000001) -> 1.2381075 | G45: =IFERROR(__xludf.DUMMYFUNCTION("GOOGLEFINANCE(""CURRENCY:EURUSD"") * H45"),0.08534249999999999) -> 0.0853425 | H45: 0.075
A48: outbud | B48: 5880 | C48: =D44*B48 -> 66.90852
A49: inbund | B49: =0.5*B48 -> 2940 | C49: =B49*D44 -> 33.45426

Sheet Master
A1: Questionnaires
A2: Telocome | F2: Tokens
A3: number of daily questionnaires | C3: 0 | F3: input tokens per interaction | H3: 7000
A4: number of days in the a month - how many time it will be used in a month | C4: 30 | F4: output tokens per interaction | H4: 340
A5: Number of Questions per Filler | C5: 2 | F5: Total number of questions a month | H5: =C3*C4*C5+C8*C9*C10+C13*C14*C15+C18*C19*C20 -> 6
A6: number of outbund in a month | C6: =(C5*C24+1)*C3*C4 -> 0 | F6: Total input tokens a month | H6: =H5*H3 -> 42000
A7: number of inbound in a month | C7: =C3*C4*C5 -> 0 | F7: Total output tokens a month | H7: =H5*H4 -> 2040
A8: number of weekly questionnaires | C8: 0 | F8: Total input tokens costs a month | H8: =Management!I5*H6 -> 0.0105
A9: number of weeks in the a month - how many time it will be used in a month | C9: 4 | F9: Total output tokens costs a month | H9: =Management!I6*H7 -> 0.00306
A10: Number of Questions per Filler | C10: 2
A11: number of outbund in a month | C11: =(C10*C24+1)*C8*C9 -> 0 | F11: Total tokens costs for quesionnaires a month | H11: =H8+H9 -> 0.01356
A12: number of inbound in a month | C12: =C8*C9*C10 -> 0
A13: number of monthly questionnaires | C13: 1
A14: number of month in the a month - how many time it will be used in a month | C14: 1
A15: Number of Questions per Filler | C15: 6
A16: number of outbund in a month | C16: =(C15*C24+1)*C13*C14 -> 10
A17: number of inbound in a month | C17: =C13*C14*C15 -> 6
A18: number of yearly questionnaires | C18: 0
A19: number of year in the a month - how many time it will be used in a month | C19: =1/12 -> 0.083333333
A20: Number of Questions per Filler | C20: 0
A21: number of outbund in a month | C21: =(C19*C24+1)*C18*C20 -> 0
A22: number of inbound in a month | C22: =C18*C20*C19 -> 0
A24: Number of Messages/Questions Ratio | C24: 1.5 | D24: Cost in USD | E24: Total in USD
A25: Number of outbund SMS - Monthly per citizen | C25: =SUM(C6,C11,C16,C21) -> 10 | D25: =Management!C6 -> 0.0853425 | E25: =C25*D25 -> 0.853425
A26: Number of inbound SMS - Monthly per citizen | C26: =SUM(C22,C17,C12,C7) -> 6 | D26: =Management!C7 -> 0.011379 | E26: =C26*D26 -> 0.068274
A28: Total costs a month | G28: =SUM(E25:E26,H11) -> 0.935259
A30: Broadcast
A31: Telocome | F31: Tokens
A32: number of daily Broadcasts | C32: 1 | F32: input tokens per interaction | H32: 7000
A33: number of days in the a month - how many time it will be used in a month | C33: 30 | F33: output tokens per interaction | H33: 340
A34: number of weekly Broadcasts | C34: 0 | F34: Total number of interactions a month | H34: =(C32*C33+C34*C35+C36*C37+C38*C39)*C45 -> 6
A35: number of weeks in the a month - how many time it will be used in a month | C35: 4 | F35: Total input tokens a month | H35: =H34*H32 -> 42000
A36: number of monthly Broadcasts | C36: 0 | F36: Total output tokens a month | H36: =H34*H33 -> 2040
A37: number of month in the a month - how many time it will be used in a month | C37: 1 | F37: Total input tokens costs a month | H37: =Management!I5*H35 -> 0.0105
A38: number of yearly Broadcasts | C38: 0 | F38: Total output tokens costs a month | H38: =Management!I6*H36 -> 0.00306
A39: number of year in the a month - how many time it will be used in a month | C39: =1/12 -> 0.083333333
A40: Total Number of Broadcasts a month | C40: =C32*C33+C34*C35+C36*C37+C38*C39 -> 30 | F40: Total tokens costs for broadcast a month | H40: =H37+H38 -> 0.01356
A41: Number of SMS per Broadcast - outbound only without conversation | C41: 2
A42: Number of SMS per Broadcast - outbound only with conversation | C42: 3
A43: Number of SMS per Broadcast - inbound only with conversation | C43: 1
...

Sheet Over all offer
C3: Agentes | D3: per contact | E3: all contacts | F3: margin | G3: Total per contact | H3: Total all contacts | I3: Basic | J3: Extra
C4: M&E Agent | D4: ='M&E Agent'!B76 -> 1.4955819 | E4: ='M&E Agent'!B77 -> 246.77101 | F4: 0.6 | G4: =D4+(D4*F4) -> 2.392931 | H4: =E4+(E4*F4) -> 394.83362 | I4: TRUE | J4: FALSE
C5: Bee Keepr Agent | D5: ='Bee Keepr Agent'!B76 -> 0.7775903 | E5: ='Bee Keepr Agent'!B77 -> 128.3024 | F5: 0.6 | G5: =D5+(D5*F5) -> 1.2441445 | H5: =E5+(E5*F5) -> 205.28384 | I5: TRUE | J5: FALSE
C6: Pest Diagnosis Agent | D6: ='Pest Diagnosis Agent'!B76 -> 1.0803081 | E6: ='Pest Diagnosis Agent'!B77 -> 178.25083 | F6: 0.6 | G6: =D6+(D6*F6) -> 1.7284929 | H6: =E6+(E6*F6) -> 285.20133 | I6: FALSE | J6: TRUE
C7: Customer Service Agent | D7: ='Customer Service Agent'!B76 -> 7.6412673 | E7: ='Customer Service Agent'!B77 -> 76.412672 | F7: 0.4 | G7: =D7+(D7*F7) -> 10.697774 | H7: =E7+(E7*F7) -> 106.97774 | I7: FALSE | J7: TRUE
G8: =G4*I4+G5*I5+G6*I6+G7*I7 -> 3.6370755 | H8: =H4*I4+H5*I5+H6*I6+H7*I7 -> 600.11746
C10: onbording | D10: monthly plan | E10: yearly plan
C11: setup | D11: =Management!C8 -> 22.64421 | E11: =Management!D8 -> 11.26521
C12: subscription | D12: =Management!C9 -> 93.02321 | E12: =Management!D9 -> 81.64421
C13: Total per year | D13: =D11+(D12*11) -> 1045.8995 | E13: =E11+(E12*11) -> 909.35152
C17: Basic | D17: monthly plan | E17: yearly plan
C18: Total all agents + subscription | D18: =H8+D12 -> 693.14067 | E18: =H8+E12 -> 681.76167
C19: Total all agents + subscription per contact | D19: =D18/Management!C11 -> 4.2008525 | E19: =E18/Management!C11 -> 4.1318889
C22: Extra
C23: Total all agents | D23: =H4*J4+H5*J5+H6*J6+H7*J7 -> 392.17907
C24: Total all agentt per contact | D24: =G4*J4+G5*J5+G6*J6+G7*J7 -> 12.426267

Sheet Customer Service Agent
A1: Questionnaires
A2: Telocome | F2: Tokens
A3: number of daily questionnaires | C3: 0 | F3: input tokens per interaction | H3: 7000
A4: number of days in the a month - how many time it will be used in a month | C4: 30 | F4: output tokens per interaction | H4: 340
A5: Number of Questions per Filler | C5: 2 | F5: Total number of questions a month | H5: =C3*C4*C5+C8*C9*C10+C13*C14*C15+C18*C19*C20 -> 6
A6: number of outbund in a month | C6: =(C5*C24+1)*C3*C4 -> 0 | F6: Total input tokens a month | H6: =H5*H3 -> 42000
A7: number of inbound in a month | C7: =C3*C4*C5 -> 0 | F7: Total output tokens a month | H7: =H5*H4 -> 2040
A8: number of weekly questionnaires | C8: 0 | F8: Total input tokens costs a month | H8: =Management!I5*H6 -> 0.0105
A9: number of weeks in the a month - how many time it will be used in a month | C9: 4 | F9: Total output tokens costs a month | H9: =Management!I6*H7 -> 0.00306
A10: Number of Questions per Filler | C10: 2
A11: number of outbund in a month | C11: =(C10*C24+1)*C8*C9 -> 0 | F11: Total tokens costs for quesionnaires a month | H11: =H8+H9 -> 0.01356
A12: number of inbound in a month | C12: =C8*C9*C10 -> 0
A13: number of monthly questionnaires | C13: 1
A14: number of month in the a month - how many time it will be used in a month | C14: 1
A15: Number of Questions per Filler | C15: 6
A16: number of outbund in a month | C16: =(C15*C24+1)*C13*C14 -> 10
A17: number of inbound in a month | C17: =C13*C14*C15 -> 6
A18: number of yearly questionnaires | C18: 0
A19: number of year in the a month - how many time it will be used in a month | C19: =1/12 -> 0.083333333
A20: Number of Questions per Filler | C20: 0
A21: number of outbund in a month | C21: =(C19*C24+1)*C18*C20 -> 0
A22: number of inbound in a month | C22: =C18*C20*C19 -> 0
A24: Number of Messages/Questions Ratio | C24: 1.5 | D24: Cost in USD | E24: Total in USD
A25: Number of outbund SMS - Monthly per citizen | C25: =SUM(C6,C11,C16,C21) -> 10 | D25: =Management!C6 -> 0.0853425 | E25: =C25*D25 -> 0.853425
A26: Number of inbound SMS - Monthly per citizen | C26: =SUM(C22,C17,C12,C7) -> 6 | D26: =Management!C7 -> 0.011379 | E26: =C26*D26 -> 0.068274
A28: Total costs a month | G28: =SUM(E25:E26,H11) -> 0.935259
A30: Broadcast
A31: Telocome | F31: Tokens
A32: number of daily Broadcasts | C32: 1 | F32: input tokens per interaction | H32: 7000
A33: number of days in the a month - how many time it will be used in a month | C33: 30 | F33: output tokens per interaction | H33: 340
A34: number of weekly Broadcasts | C34: 0 | F34: Total number of interactions a month | H34: =(C32*C33+C34*C35+C36*C37+C38*C39)*C45 -> 6
A35: number of weeks in the a month - how many time it will be used in a month | C35: 4 | F35: Total input tokens a month | H35: =H34*H32 -> 42000
A36: number of monthly Broadcasts | C36: 0 | F36: Total output tokens a month | H36: =H34*H33 -> 2040
A37: number of month in the a month - how many time it will be used in a month | C37: 1 | F37: Total input tokens costs a month | H37: =Management!I5*H35 -> 0.0105
A38: number of yearly Broadcasts | C38: 0 | F38: Total output tokens costs a month | H38: =Management!I6*H36 -> 0.00306
A39: number of year in the a month - how many time it will be used in a month | C39: =1/12 -> 0.083333333
A40: Total Number of Broadcasts a month | C40: =C32*C33+C34*C35+C36*C37+C38*C39 -> 30 | F40: Total tokens costs for broadcast a month | H40: =H37+H38 -> 0.01356
A41: Number of SMS per Broadcast - outbound only without conversation | C41: 2
A42: Number of SMS per Broadcast - outbound only with conversation | C42: 3
A43: Number of SMS per Broadcast - inbound only with conversation | C43: 1
...

Sheet Pest Diagnosis Agent
A1: Questionnaires
A2: Telocome | F2: Tokens
A3: number of daily questionnaires | C3: 0 | F3: input tokens per interaction | H3: 10000
A4: number of days in the a month - how many time it will be used in a month | C4: 30 | F4: output tokens per interaction | H4: 500
A5: Number of Questions per Filler | C5: 2 | F5: Total number of questions a month | H5: =C3*C4*C5+C8*C9*C10+C13*C14*C15+C18*C19*C20 -> 0
A6: number of outbund in a month | C6: =(C5*C24+1)*C3*C4 -> 0 | F6: Total input tokens a month | H6: =H5*H3 -> 0
A7: number of inbound in a month | C7: =C3*C4*C5 -> 0 | F7: Total output tokens a month | H7: =H5*H4 -> 0
A8: number of weekly questionnaires | C8: 0 | F8: Total input tokens costs a month | H8: =Management!I5*H6 -> 0
A9: number of weeks in the a month - how many time it will be used in a month | C9: 4 | F9: Total output tokens costs a month | H9: =Management!I6*H7 -> 0
A10: Number of Questions per Filler | C10: 2
A11: number of outbund in a month | C11: =(C10*C24+1)*C8*C9 -> 0 | F11: Total tokens costs for quesionnaires a month | H11: =H8+H9 -> 0
A12: number of inbound in a month | C12: =C8*C9*C10 -> 0
A13: number of monthly questionnaires | C13: 0
A14: number of month in the a month - how many time it will be used in a month | C14: 1
A15: Number of Questions per Filler | C15: 6
A16: number of outbund in a month | C16: =(C15*C24+1)*C13*C14 -> 0
A17: number of inbound in a month | C17: =C13*C14*C15 -> 0
A18: number of yearly questionnaires | C18: 0
A19: number of year in the a month - how many time it will be used in a month | C19: =1/12 -> 0.083333333
A20: Number of Questions per Filler | C20: 0
A21: number of outbund in a month | C21: =(C19*C24+1)*C18*C20 -> 0
A22: number of inbound in a month | C22: =C18*C20*C19 -> 0
A24: Number of Messages/Questions Ratio | C24: 1.5 | D24: Cost in USD | E24: Total in USD
A25: Number of outbund SMS - Monthly per citizen | C25: =SUM(C6,C11,C16,C21) -> 0 | D25: =Management!C6 -> 0.0853425 | E25: =C25*D25 -> 0
A26: Number of inbound SMS - Monthly per citizen | C26: =SUM(C22,C17,C12,C7) -> 0 | D26: =Management!C7 -> 0.011379 | E26: =C26*D26 -> 0
A28: Total costs a month | G28: =SUM(E25:E26,H11) -> 0
A30: Broadcast
A31: Telocome | F31: Tokens
A32: number of daily Broadcasts | C32: 0 | F32: input tokens per interaction | H32: 10000
A33: number of days in the a month - how many time it will be used in a month | C33: 30 | F33: output tokens per interaction | H33: 500
A34: number of weekly Broadcasts | C34: 0 | F34: Total number of interactions a month | H34: =(C32*C33+C34*C35+C36*C37+C38*C39)*C45 -> 0.4
A35: number of weeks in the a month - how many time it will be used in a month | C35: 4 | F35: Total input tokens a month | H35: =H34*H32 -> 4000
A36: number of monthly Broadcasts | C36: 2 | F36: Total output tokens a month | H36: =H34*H33 -> 200
A37: number of month in the a month - how many time it will be used in a month | C37: 1 | F37: Total input tokens costs a month | H37: =Management!I5*H35 -> 0.001
A38: number of yearly Broadcasts | C38: 0 | F38: Total output tokens costs a month | H38: =Management!I6*H36 -> 0.0003
A39: number of year in the a month - how many time it will be used in a month | C39: =1/12 -> 0.083333333
A40: Total Number of Broadcasts a month | C40: =C32*C33+C34*C35+C36*C37+C38*C39 -> 2 | F40: Total tokens costs for broadcast a month | H40: =H37+H38 -> 0.0013
A41: Number of SMS per Broadcast - outbound only without conversation | C41: 2
A42: Number of SMS per Broadcast - outbound only with conversation | C42: 3
A43: Number of SMS per Broadcast - inbound only with conversation | C43: 1
...

Sheet Bee Keepr Agent
A1: Questionnaires
A2: Telocome | F2: Tokens
A3: number of daily questionnaires | C3: 0 | F3: input tokens per interaction | H3: 7000
A4: number of days in the a month - how many time it will be used in a month | C4: 30 | F4: output tokens per interaction | H4: 340
A5: Number of Questions per Filler | C5: 2 | F5: Total number of questions a month | H5: =C3*C4*C5+C8*C9*C10+C13*C14*C15+C18*C19*C20 -> 0
A6: number of outbund in a month | C6: =(C5*C24+1)*C3*C4 -> 0 | F6: Total input tokens a month | H6: =H5*H3 -> 0
A7: number of inbound in a month | C7: =C3*C4*C5 -> 0 | F7: Total output tokens a month | H7: =H5*H4 -> 0
A8: number of weekly questionnaires | C8: 0 | F8: Total input tokens costs a month | H8: =Management!I5*H6 -> 0
A9: number of weeks in the a month - how many time it will be used in a month | C9: 4 | F9: Total output tokens costs a month | H9: =Management!I6*H7 -> 0
A10: Number of Questions per Filler | C10: 2
A11: number of outbund in a month | C11: =(C10*C24+1)*C8*C9 -> 0 | F11: Total tokens costs for quesionnaires a month | H11: =H8+H9 -> 0
A12: number of inbound in a month | C12: =C8*C9*C10 -> 0
A13: number of monthly questionnaires | C13: 0
A14: number of month in the a month - how many time it will be used in a month | C14: 1
A15: Number of Questions per Filler | C15: 6
A16: number of outbund in a month | C16: =(C15*C24+1)*C13*C14 -> 0
A17: number of inbound in a month | C17: =C13*C14*C15 -> 0
A18: number of yearly questionnaires | C18: 0
A19: number of year in the a month - how many time it will be used in a month | C19: =1/12 -> 0.083333333
A20: Number of Questions per Filler | C20: 0
A21: number of outbund in a month | C21: =(C19*C24+1)*C18*C20 -> 0
A22: number of inbound in a month | C22: =C18*C20*C19 -> 0
A24: Number of Messages/Questions Ratio | C24: 1.5 | D24: Cost in USD | E24: Total in USD
A25: Number of outbund SMS - Monthly per citizen | C25: =SUM(C6,C11,C16,C21) -> 0 | D25: =Management!C6 -> 0.0853425 | E25: =C25*D25 -> 0
A26: Number of inbound SMS - Monthly per citizen | C26: =SUM(C22,C17,C12,C7) -> 0 | D26: =Management!C7 -> 0.011379 | E26: =C26*D26 -> 0
A28: Total costs a month | G28: =SUM(E25:E26,H11) -> 0
A30: Broadcast
A31: Telocome | F31: Tokens
A32: number of daily Broadcasts | C32: 0 | F32: input tokens per interaction | H32: 7000
A33: number of days in the a month - how many time it will be used in a month | C33: 30 | F33: output tokens per interaction | H33: 340
A34: number of weekly Broadcasts | C34: 0 | F34: Total number of interactions a month | H34: =(C32*C33+C34*C35+C36*C37+C38*C39)*C45 -> 0.4
A35: number of weeks in the a month - how many time it will be used in a month | C35: 4 | F35: Total input tokens a month | H35: =H34*H32 -> 2800
A36: number of monthly Broadcasts | C36: 2 | F36: Total output tokens a month | H36: =H34*H33 -> 136
A37: number of month in the a month - how many time it will be used in a month | C37: 1 | F37: Total input tokens costs a month | H37: =Management!I5*H35 -> 0.0007
A38: number of yearly Broadcasts | C38: 0 | F38: Total output tokens costs a month | H38: =Management!I6*H36 -> 0.000204
A39: number of year in the a month - how many time it will be used in a month | C39: =1/12 -> 0.083333333
A40: Total Number of Broadcasts a month | C40: =C32*C33+C34*C35+C36*C37+C38*C39 -> 2 | F40: Total tokens costs for broadcast a month | H40: =H37+H38 -> 0.000904
A41: Number of SMS per Broadcast - outbound only without conversation | C41: 2
A42: Number of SMS per Broadcast - outbound only with conversation | C42: 3
A43: Number of SMS per Broadcast - inbound only with conversation | C43: 1
...

Sheet M&E Agent
A1: Questionnaires
A2: Telocome | F2: Tokens
A3: number of daily questionnaires | C3: 0 | F3: input tokens per interaction | H3: 2000
A4: number of days in the a month - how many time it will be used in a month | C4: 30 | F4: output tokens per interaction | H4: 50
A5: Number of Questions per Filler | C5: 2 | F5: Total number of questions a month | H5: =C3*C4*C5+C8*C9*C10+C13*C14*C15+C18*C19*C20 -> 6
A6: number of outbund in a month | C6: =(C5*C24+1)*C3*C4 -> 0 | F6: Total input tokens a month | H6: =H5*H3 -> 12000
A7: number of inbound in a month | C7: =C3*C4*C5 -> 0 | F7: Total output tokens a month | H7: =H5*H4 -> 300
A8: number of weekly questionnaires | C8: 0 | F8: Total input tokens costs a month | H8: =Management!I5*H6 -> 0.003
A9: number of weeks in the a month - how many time it will be used in a month | C9: 4 | F9: Total output tokens costs a month | H9: =Management!I6*H7 -> 0.00045
A10: Number of Questions per Filler | C10: 2
A11: number of outbund in a month | C11: =(C10*C24+1)*C8*C9 -> 0 | F11: Total tokens costs for quesionnaires a month | H11: =H8+H9 -> 0.00345
A12: number of inbound in a month | C12: =C8*C9*C10 -> 0
A13: number of monthly questionnaires | C13: 1
A14: number of month in the a month - how many time it will be used in a month | C14: 1
A15: Number of Questions per Filler | C15: 6
A16: number of outbund in a month | C16: =(C15*C24+1)*C13*C14 -> 10
A17: number of inbound in a month | C17: =C13*C14*C15 -> 6
A18: number of yearly questionnaires | C18: 0
A19: number of year in the a month - how many time it will be used in a month | C19: =1/12 -> 0.083333333
A20: Number of Questions per Filler | C20: 0
A21: number of outbund in a month | C21: =(C19*C24+1)*C18*C20 -> 0
A22: number of inbound in a month | C22: =C18*C20*C19 -> 0
A24: Number of Messages/Questions Ratio | C24: 1.5 | D24: Cost in USD | E24: Total in USD
A25: Number of outbund SMS - Monthly per citizen | C25: =SUM(C6,C11,C16,C21) -> 10 | D25: =Management!C6 -> 0.0853425 | E25: =C25*D25 -> 0.853425
A26: Number of inbound SMS - Monthly per citizen | C26: =SUM(C22,C17,C12,C7) -> 6 | D26: =Management!C7 -> 0.011379 | E26: =C26*D26 -> 0.068274
A28: Total costs a month | G28: =SUM(E25:E26,H11) -> 0.925149
A30: Broadcast
A31: Telocome | F31: Tokens
A32: number of daily Broadcasts | F32: input tokens per interaction | H32: 2000
A33: number of days in the a month - how many time it will be used in a month | C33: 30 | F33: output tokens per interaction | H33: 50
A34: number of weekly Broadcasts | C34: 0 | F34: Total number of interactions a month | H34: =(C32*C33+C34*C35+C36*C37+C38*C39)*C45 -> 0.6
A35: number of weeks in the a month - how many time it will be used in a month | C35: 4 | F35: Total input tokens a month | H35: =H34*H32 -> 1200
A36: number of monthly Broadcasts | C36: 3 | F36: Total output tokens a month | H36: =H34*H33 -> 30
A37: number of month in the a month - how many time it will be used in a month | C37: 1 | F37: Total input tokens costs a month | H37: =Management!I5*H35 -> 0.0003
A38: number of yearly Broadcasts | C38: 0 | F38: Total output tokens costs a month | H38: =Management!I6*H36 -> 4.5e-05
A39: number of year in the a month - how many time it will be used in a month | C39: =1/12 -> 0.083333333
A40: Total Number of Broadcasts a month | C40: =C32*C33+C34*C35+C36*C37+C38*C39 -> 3 | F40: Total tokens costs for broadcast a month | H40: =H37+H38 -> 0.000345
A41: Number of SMS per Broadcast - outbound only without conversation | C41: 2
A42: Number of SMS per Broadcast - outbound only with conversation | C42: 3
A43: Number of SMS per Broadcast - inbound only with conversation | C43: 1
...
